Workbook

Sheet Samata1
B1: kaina | C1: POZICIJA | F1: kaina | G1: POZICIJA | J1: kaina | K1: GAMYBA | N1: kaina
G2: Corten lakstai 2mm | J2: 30 | K2: Bendras LMDP darbo ikainis | N2: 15
A3: lmdp azuolas ulmas | B3: 10 | C3: lukstas 0,5mm ALPI | F3: 12 | G3: masyvas tasas 60x60 | J3: 17 | K3: Stalciaus montavimas | N3: 35
A4: stiklas | B4: 40 | C4: Tehnistone (Noble Pro Frost) | F4: 165 | G4: NP lentynos/stelazai/etc | J4: 350 | K4: Apvalaus frezavimo taskas | N4: 10
A5: metalas 25x25 | B5: 2.2 | C5: stalvirsis Hi-MACS T019 New Moon | G5: Karkasine LMDP Stone Beige, K680PD (BE KAINOS) | J5: 18 | K5: Furnituros montavimas | N5: 35
A6: metal dazymas | B6: 5 | C6: faneruotes laminavimas | F6: 15 | G6: Karkasine Kronospan 0164 Anthracite | J6: 12 | K6: Frezavimas metras | N6: 15
A7: zalvaris plotas | B7: 150 | C7: LMDP korpusine | F7: 12 | G7: Karkasine LMDP (prie luksto baldu) | J7: 18 | K7: smulkios furnituros montavimas | N7: 3
A8: zalvaris krastine | B8: 20 | C8: MDF paprastas | F8: 10 | G8: Lankstai | J8: 6 | K8: Furnituros montavimas | N8: 10
A9: metal vamzdis d32 | B9: 6.4 | C9: 2 tasku rankena | F9: 20 | G9: Push | J9: 6 | K9: LED Trafas | N9: 70
A10: blum tandembox | B10: 65 | C10: 1 tasko rankena | F10: 15 | G10: Spintos rankena | J10: 25
A11: blum lankstas | B11: 3 | C11: 4mm nerudijancio plieno lakstas | F11: 85 | G11: Lukstas | J11: 25 | K11: Stalcius isorinis (Lukstas) | N11: 130
A12: MDF zalias | B12: 20 | C12: MDF fasadai frezavimas su medziaga | F12: 80 | G12: kabykla | J12: 15 | K12: Stalcius vidinis | N12: 90
C13: 19mm lukstas FMDP | F13: 20 | G13: GOLA profilis | J13: 25
A14: Masyvas 20-22 | B14: 300 | C14: masyvas tasas 40x40 | F14: 10 | G14: Kampine sistema | J14: 500
A15: LED frezavimas | B15: 12 | C15: veidrodis sendintas 100-200 | F15: 150 | K15: Ukine spinta https://www.furnitanas.lt/sistema-495-su-lentynomis-liro | N15: 750
A16: lakavimas | B16: 30 | C16: veidrodis paprastas | F16: 40 | K16: Spintos montavimas | N16: 50
A17: traf dim | B17: 80 | C17: lmdp K090 | F17: 18
A18: traf | B18: 40 | C18: lmdp 0166 | F18: 23
A19: beicavimas | B19: 20 | C19: fanera korpusams | F19: 23
A20: dazymas | B20: 60 | C20: metalas 20x20 su kofu | F20: 35
A21: Paprastos kojos tekinimas | B21: 8 | C21: kabyklos metals su kofu | F21: 55
A22: LED frezavimas+profilis+LED 12V | B22: 40 | C22: LMDP negro FENIX | F22: 111
A23: LED frezavimas+profilis+LED 24V | B23: 50 | C23: metalas 30x30 | F23: 3
A25: uzduotis | B25: komentaras | C25: kvm/vnt/m | D25: kaina | E25: savikaina | F25: 1.4 | G25: METAL | H25: LMDP | I25: PASLAUGA | J25: MASYVAS | K25: FURNITURA | L25: STIKLAS | M25: BE KOFO | N25: - | O25: - | P25: -
G26: 5 | H26: 3 | I26: 1.8 | J26: 1.1 | K26: 2 | L26: 2 | M26: 1 | N26: 0 | O26: 0 | P26: 0
A27: 1. Koridoriaus spinta | E27: =C27*D27 -> 0 | F27: =SUM(G28:M41)*$F$25 -> 2882.091 | G27: =IF(B27="metalas",E27*$G$26,0) -> 0 | H27: =IF(B27="LMDP",E27*$H$26,0) -> 0 | I27: =IF(B27="paslauga",E27*$I$26,0) -> 0 | J27: =IF(B27="masyvas",E27*$J$26,0) -> 0 | K27: =IF(B27="furnitura",E27*$K$26,0) -> 0 | L27: =IF(B27="stiklas",E27*$L$26,0) -> 0 | M27: =IF(B27="be kofo",E27*$M$26,0) -> 0 | N27: =IF(G27="paslauga",J27*$I$26,0) -> 0 | O27: =IF(G27="masyvas",J27*$J$26,0) -> 0 | P27: =IF(G27="furnitura",J27*$K$26,0) -> 0
A28: Bendras | B28: LMDP | C28: =C29+C30 -> 19.9442 | D28: =N2 -> 15 | E28: =C28*D28 -> 299.163 | G28: =IF(B28="metalas",E28*$G$26,0) -> 0 | H28: =IF(B28="LMDP",E28*$H$26,0) -> 897.489 | I28: =IF(B28="paslauga",E28*$I$26,0) -> 0 | J28: =IF(B28="masyvas",E28*$J$26,0) -> 0 | K28: =IF(B28="furnitura",E28*$K$26,0) -> 0 | L28: =IF(B28="stiklas",E28*$L$26,0) -> 0 | M28: =IF(B28="be kofo",E28*$M$26,0) -> 0 | N28: =IF(G28="paslauga",J28*$I$26,0) -> 0 | O28: =IF(G28="masyvas",J28*$J$26,0) -> 0 | P28: =IF(G28="furnitura",J28*$K$26,0) -> 0
A29: Karkasas | B29: masyvas | C29: =3.02*0.6*3+1.505*0.6*6+3.02*1.505 -> 15.3991 | D29: =J7 -> 18 | E29: =C29*D29 -> 277.1838 | G29: =IF(B29="metalas",E29*$G$26,0) -> 0 | H29: =IF(B29="LMDP",E29*$H$26,0) -> 0 | I29: =IF(B29="paslauga",E29*$I$26,0) -> 0 | J29: =IF(B29="masyvas",E29*$J$26,0) -> 304.90218 | K29: =IF(B29="furnitura",E29*$K$26,0) -> 0 | L29: =IF(B29="stiklas",E29*$L$26,0) -> 0 | M29: =IF(B29="be kofo",E29*$M$26,0) -> 0 | N29: =IF(G29="paslauga",J29*$I$26,0) -> 0 | O29: =IF(G29="masyvas",J29*$J$26,0) -> 0 | P29: =IF(G29="furnitura",J29*$K$26,0) -> 0
A30: fasadas | B30: masyvas | C30: =3.02*1.505 -> 4.5451 | D30: =J11 -> 25 | E30: =C30*D30 -> 113.6275 | G30: =IF(B30="metalas",E30*$G$26,0) -> 0 | H30: =IF(B30="LMDP",E30*$H$26,0) -> 0 | I30: =IF(B30="paslauga",E30*$I$26,0) -> 0 | J30: =IF(B30="masyvas",E30*$J$26,0) -> 124.99025 | K30: =IF(B30="furnitura",E30*$K$26,0) -> 0 | L30: =IF(B30="stiklas",E30*$L$26,0) -> 0 | M30: =IF(B30="be kofo",E30*$M$26,0) -> 0 | N30: =IF(G30="paslauga",J30*$I$26,0) -> 0 | O30: =IF(G30="masyvas",J30*$J$26,0) -> 0 | P30: =IF(G30="furnitura",J30*$K$26,0) -> 0
A31: lankstai | B31: furnitura | C31: =3*4+2*2 -> 16 | D31: =J8 -> 6 | E31: =C31*D31 -> 96 | G31: =IF(B31="metalas",E31*$G$26,0) -> 0 | H31: =IF(B31="LMDP",E31*$H$26,0) -> 0 | I31: =IF(B31="paslauga",E31*$I$26,0) -> 0 | J31: =IF(B31="masyvas",E31*$J$26,0) -> 0 | K31: =IF(B31="furnitura",E31*$K$26,0) -> 192 | L31: =IF(B31="stiklas",E31*$L$26,0) -> 0 | M31: =IF(B31="be kofo",E31*$M$26,0) -> 0 | N31: =IF(G31="paslauga",J31*$I$26,0) -> 0 | O31: =IF(G31="masyvas",J31*$J$26,0) -> 0 | P31: =IF(G31="furnitura",J31*$K$26,0) -> 0
A32: Push | B32: furnitura | C32: 2 | D32: =J9 -> 6 | E32: =C32*D32 -> 12 | G32: =IF(B32="metalas",E32*$G$26,0) -> 0 | H32: =IF(B32="LMDP",E32*$H$26,0) -> 0 | I32: =IF(B32="paslauga",E32*$I$26,0) -> 0 | J32: =IF(B32="masyvas",E32*$J$26,0) -> 0 | K32: =IF(B32="furnitura",E32*$K$26,0) -> 24 | L32: =IF(B32="stiklas",E32*$L$26,0) -> 0 | M32: =IF(B32="be kofo",E32*$M$26,0) -> 0 | N32: =IF(G32="paslauga",J32*$I$26,0) -> 0 | O32: =IF(G32="masyvas",J32*$J$26,0) -> 0 | P32: =IF(G32="furnitura",J32*$K$26,0) -> 0
A33: Rankena | B33: furnitura | C33: 3 | D33: =J10 -> 25 | E33: =C33*D33 -> 75 | G33: =IF(B33="metalas",E33*$G$26,0) -> 0 | H33: =IF(B33="LMDP",E33*$H$26,0) -> 0 | I33: =IF(B33="paslauga",E33*$I$26,0) -> 0 | J33: =IF(B33="masyvas",E33*$J$26,0) -> 0 | K33: =IF(B33="furnitura",E33*$K$26,0) -> 150 | L33: =IF(B33="stiklas",E33*$L$26,0) -> 0 | M33: =IF(B33="be kofo",E33*$M$26,0) -> 0 | N33: =IF(G33="paslauga",J33*$I$26,0) -> 0 | O33: =IF(G33="masyvas",J33*$J$26,0) -> 0 | P33: =IF(G33="furnitura",J33*$K$26,0) -> 0
A34: smulkios furnituros montavimas | B34: be kofo | C34: =C31+C32+C33 -> 21 | D34: =N7 -> 3 | E34: =C34*D34 -> 63 | G34: =IF(B34="metalas",E34*$G$26,0) -> 0 | H34: =IF(B34="LMDP",E34*$H$26,0) -> 0 | I34: =IF(B34="paslauga",E34*$I$26,0) -> 0 | J34: =IF(B34="masyvas",E34*$J$26,0) -> 0 | K34: =IF(B34="furnitura",E34*$K$26,0) -> 0 | L34: =IF(B34="stiklas",E34*$L$26,0) -> 0 | M34: =IF(B34="be kofo",E34*$M$26,0) -> 63 | N34: =IF(G34="paslauga",J34*$I$26,0) -> 0 | O34: =IF(G34="masyvas",J34*$J$26,0) -> 0 | P34: =IF(G34="furnitura",J34*$K$26,0) -> 0
A35: Kabykla | B35: be kofo | C35: 3 | D35: =J12 -> 15 | E35: =C35*D35 -> 45 | G35: =IF(B35="metalas",E35*$G$26,0) -> 0 | H35: =IF(B35="LMDP",E35*$H$26,0) -> 0 | I35: =IF(B35="paslauga",E35*$I$26,0) -> 0 | J35: =IF(B35="masyvas",E35*$J$26,0) -> 0 | K35: =IF(B35="furnitura",E35*$K$26,0) -> 0 | L35: =IF(B35="stiklas",E35*$L$26,0) -> 0 | M35: =IF(B35="be kofo",E35*$M$26,0) -> 45 | N35: =IF(G35="paslauga",J35*$I$26,0) -> 0 | O35: =IF(G35="masyvas",J35*$J$26,0) -> 0 | P35: =IF(G35="furnitura",J35*$K$26,0) -> 0
A36: furnituros montavimas | B36: be kofo | C36: 3 | D36: =N8 -> 10 | E36: =C36*D36 -> 30 | G36: =IF(B36="metalas",E36*$G$26,0) -> 0 | H36: =IF(B36="LMDP",E36*$H$26,0) -> 0 | I36: =IF(B36="paslauga",E36*$I$26,0) -> 0 | J36: =IF(B36="masyvas",E36*$J$26,0) -> 0 | K36: =IF(B36="furnitura",E36*$K$26,0) -> 0 | L36: =IF(B36="stiklas",E36*$L$26,0) -> 0 | M36: =IF(B36="be kofo",E36*$M$26,0) -> 30 | N36: =IF(G36="paslauga",J36*$I$26,0) -> 0 | O36: =IF(G36="masyvas",J36*$J$26,0) -> 0 | P36: =IF(G36="furnitura",J36*$K$26,0) -> 0
A37: beicavimas | B37: be kofo | C37: =C30 -> 4.5451 | D37: =B19 -> 20 | E37: =C37*D37 -> 90.902 | G37: =IF(B37="metalas",E37*$G$26,0) -> 0 | H37: =IF(B37="LMDP",E37*$H$26,0) -> 0 | I37: =IF(B37="paslauga",E37*$I$26,0) -> 0 | J37: =IF(B37="masyvas",E37*$J$26,0) -> 0 | K37: =IF(B37="furnitura",E37*$K$26,0) -> 0 | L37: =IF(B37="stiklas",E37*$L$26,0) -> 0 | M37: =IF(B37="be kofo",E37*$M$26,0) -> 90.902 | N37: =IF(G37="paslauga",J37*$I$26,0) -> 0 | O37: =IF(G37="masyvas",J37*$J$26,0) -> 0 | P37: =IF(G37="furnitura",J37*$K$26,0) -> 0
A38: lakavimas | B38: be kofo | C38: =C30 -> 4.5451 | D38: =B16 -> 30 | E38: =C38*D38 -> 136.353 | G38: =IF(B38="metalas",E38*$G$26,0) -> 0 | H38: =IF(B38="LMDP",E38*$H$26,0) -> 0 | I38: =IF(B38="paslauga",E38*$I$26,0) -> 0 | J38: =IF(B38="masyvas",E38*$J$26,0) -> 0 | K38: =IF(B38="furnitura",E38*$K$26,0) -> 0 | L38: =IF(B38="stiklas",E38*$L$26,0) -> 0 | M38: =IF(B38="be kofo",E38*$M$26,0) -> 136.353 | N38: =IF(G38="paslauga",J38*$I$26,0) -> 0 | O38: =IF(G38="masyvas",J38*$J$26,0) -> 0 | P38: =IF(G38="furnitura",J38*$K$26,0) -> 0
B39: be kofo | E39: =C39*D39 -> 0 | G39: =IF(B39="metalas",E39*$G$26,0) -> 0 | H39: =IF(B39="LMDP",E39*$H$26,0) -> 0 | I39: =IF(B39="paslauga",E39*$I$26,0) -> 0 | J39: =IF(B39="masyvas",E39*$J$26,0) -> 0 | K39: =IF(B39="furnitura",E39*$K$26,0) -> 0 | L39: =IF(B39="stiklas",E39*$L$26,0) -> 0 | M39: =IF(B39="be kofo",E39*$M$26,0) -> 0 | N39: =IF(G39="paslauga",J39*$I$26,0) -> 0 | O39: =IF(G39="masyvas",J39*$J$26,0) -> 0 | P39: =IF(G39="furnitura",J39*$K$26,0) -> 0
B40: metalas | E40: =C40*D40 -> 0 | G40: =IF(B40="metalas",E40*$G$26,0) -> 0 | H40: =IF(B40="LMDP",E40*$H$26,0) -> 0 | I40: =IF(B40="paslauga",E40*$I$26,0) -> 0 | J40: =IF(B40="masyvas",E40*$J$26,0) -> 0 | K40: =IF(B40="furnitura",E40*$K$26,0) -> 0 | L40: =IF(B40="stiklas",E40*$L$26,0) -> 0 | M40: =IF(B40="be kofo",E40*$M$26,0) -> 0 | N40: =IF(G40="paslauga",J40*$I$26,0) -> 0 | O40: =IF(G40="masyvas",J40*$J$26,0) -> 0 | P40: =IF(G40="furnitura",J40*$K$26,0) -> 0
B41: metalas | E41: =C41*D41 -> 0 | G41: =IF(B41="metalas",E41*$G$26,0) -> 0 | H41: =IF(B41="LMDP",E41*$H$26,0) -> 0 | I41: =IF(B41="paslauga",E41*$I$26,0) -> 0 | J41: =IF(B41="masyvas",E41*$J$26,0) -> 0 | K41: =IF(B41="furnitura",E41*$K$26,0) -> 0 | L41: =IF(B41="stiklas",E41*$L$26,0) -> 0 | M41: =IF(B41="be kofo",E41*$M$26,0) -> 0 | N41: =IF(G41="paslauga",J41*$I$26,0) -> 0 | O41: =IF(G41="masyvas",J41*$J$26,0) -> 0 | P41: =IF(G41="furnitura",J41*$K$26,0) -> 0
...

Sheet Korpusiniai (2)
C7: Plotis, mm | D7: Gylis, mm | E7: Aukštis, mm | G7: Fasadas | H7: Stalčiai | I7: Stalčius iš plokštės | J7: Stalčiaus aukštis | K7: Stalčiaus gylis | L7: Nugarėlė | M7: Lentynos | N7: Cokolis | O7: Pertvaros | Q7: Tarpinis | R7: Plokštės kiekis | S7: Fasadas | T7: Korpusas | U7: Stalčiai | V7: Lentynos | W7: Nugarėlė | X7: Cokolis | Y7: Pertvaros | Z7: plokštės stalčiai
C8: 1500 | D8: 1050 | E8: 800 | G8: TRUE | H8: 6 | I8: TRUE | J8: 192 | K8: 550 | L8: TRUE | M8: 0 | N8: FALSE | O8: 1 | Q8: =T8+(IF(G8=TRUE,S8,0))+(IF(H8>0,U8,0))+(IF(L8=TRUE,W8,0))+(IF(M8>0,V8,0))+(IF(N8=TRUE,X8,0))+(Y8*O8)+(IF(I8=TRUE,Z8,0)) -> 13.978452 | R8: =IF(Q8>0,Q8,0) -> 13.978452 | S8: =C8*E8/1000000 -> 1.2 | T8: =((C8*D8)+(C8*E8*2)+(2*((C8-36)*100)))/1000000 -> 4.2678 | U8: =(((((C8-36)-75)*K8)/1000000)*H8)+(((((C8-36)-87)*J8)/1000000)*H8) -> 6.170004 | V8: =((C8-36)*(D8-28))/1000000 -> 1.496208 | W8: =((C8-36)*(E8-18))/1000000 -> 1.144848 | X8: =(C8*100)/1000000 -> 0.15 | Y8: =((E8-36)*D8)/1000000 -> 0.8022 | Z8: =((C8*J8)+(K8*J8))/1000000 -> 0.3936
C9: 540 | D9: 600 | E9: 800 | G9: FALSE | H9: 3 | I9: FALSE | J9: 224 | K9: 450 | L9: TRUE | M9: 0 | N9: TRUE | O9: 0 | Q9: =T9+(IF(G9=TRUE,S9,0))+(IF(H9>0,U9,0))+(IF(L9=TRUE,W9,0))+(IF(M9>0,V9,0))+(IF(N9=TRUE,X9,0)) -> 2.596302 | R9: =IF(Q9>0,Q9,0) -> 2.596302 | S9: =C9*E9/1000000 -> 0.432 | T9: =((C9*D9)+(C9*E9*2)+(2*((C9-36)*100)))/1000000 -> 1.2888 | U9: =(((((C9-36)-75)*K9)/1000000)*H9)+(((((C9-36)-87)*J9)/1000000)*H9) -> 0.859374 | V9: =((C9-36)*(D9-28))/1000000 -> 0.288288 | W9: =((C9-36)*(E9-18))/1000000 -> 0.394128 | X9: =(C9*100)/1000000 -> 0.054 | Y9: =((E9-36)*D9)/1000000 -> 0.4584
C10: 540 | D10: 600 | E10: 800 | G10: FALSE | H10: 3 | I10: FALSE | J10: 224 | K10: 450 | L10: TRUE | M10: 0 | N10: TRUE | O10: 0 | Q10: =T10+(IF(G10=TRUE,S10,0))+(IF(H10>0,U10,0))+(IF(L10=TRUE,W10,0))+(IF(M10>0,V10,0))+(IF(N10=TRUE,X10,0)) -> 2.596302 | R10: =IF(Q10>0,Q10,0) -> 2.596302 | S10: =C10*E10/1000000 -> 0.432 | T10: =((C10*D10)+(C10*E10*2)+(2*((C10-36)*100)))/1000000 -> 1.2888 | U10: =(((((C10-36)-75)*K10)/1000000)*H10)+(((((C10-36)-87)*J10)/1000000)*H10) -> 0.859374 | V10: =((C10-36)*(D10-28))/1000000 -> 0.288288 | W10: =((C10-36)*(E10-18))/1000000 -> 0.394128 | X10: =(C10*100)/1000000 -> 0.054 | Y10: =((E10-36)*D10)/1000000 -> 0.4584
C11: 780 | D11: 600 | E11: 800 | G11: FALSE | H11: 2 | I11: FALSE | J11: 0 | K11: 0 | L11: TRUE | M11: 0 | N11: TRUE | O11: 0 | Q11: =T11+(IF(G11=TRUE,S11,0))+(IF(H11>0,U11,0))+(IF(L11=TRUE,W11,0))+(IF(M11>0,V11,0))+(IF(N11=TRUE,X11,0)) -> 2.524608 | R11: =IF(Q11>0,Q11,0) -> 2.524608 | S11: =C11*E11/1000000 -> 0.624 | T11: =((C11*D11)+(C11*E11*2)+(2*((C11-36)*100)))/1000000 -> 1.8648 | U11: =(((((C11-36)-75)*K11)/1000000)*H11)+(((((C11-36)-87)*J11)/1000000)*H11) -> 0 | V11: =((C11-36)*(D11-28))/1000000 -> 0.425568 | W11: =((C11-36)*(E11-18))/1000000 -> 0.581808 | X11: =(C11*100)/1000000 -> 0.078 | Y11: =((E11-36)*D11)/1000000 -> 0.4584
C12: 600 | D12: 600 | E12: 800 | G12: FALSE | H12: 2 | I12: FALSE | J12: 0 | K12: 0 | L12: TRUE | M12: 0 | N12: TRUE | O12: 0 | Q12: =T12+(IF(G12=TRUE,S12,0))+(IF(H12>0,U12,0))+(IF(L12=TRUE,W12,0))+(IF(M12>0,V12,0))+(IF(N12=TRUE,X12,0)) -> 1.933848 | R12: =IF(Q12>0,Q12,0) -> 1.933848 | S12: =C12*E12/1000000 -> 0.48 | T12: =((C12*D12)+(C12*E12*2)+(2*((C12-36)*100)))/1000000 -> 1.4328 | U12: =(((((C12-36)-75)*K12)/1000000)*H12)+(((((C12-36)-87)*J12)/1000000)*H12) -> 0 | V12: =((C12-36)*(D12-28))/1000000 -> 0.322608 | W12: =((C12-36)*(E12-18))/1000000 -> 0.441048 | X12: =(C12*100)/1000000 -> 0.06 | Y12: =((E12-36)*D12)/1000000 -> 0.4584
C13: 600 | D13: 600 | E13: 800 | G13: FALSE | H13: 0 | I13: FALSE | J13: 83 | K13: 550 | L13: TRUE | M13: 0 | N13: TRUE | O13: 0 | Q13: =T13+(IF(G13=TRUE,S13,0))+(IF(H13>0,U13,0))+(IF(L13=TRUE,W13,0))+(IF(M13>0,V13,0))+(IF(N13=TRUE,X13,0)) -> 1.933848 | R13: =IF(Q13>0,Q13,0) -> 1.933848 | S13: =C13*E13/1000000 -> 0.48 | T13: =((C13*D13)+(C13*E13*2)+(2*((C13-36)*100)))/1000000 -> 1.4328 | U13: =(((((C13-36)-75)*K13)/1000000)*H13)+(((((C13-36)-87)*J13)/1000000)*H13) -> 0 | V13: =((C13-36)*(D13-28))/1000000 -> 0.322608 | W13: =((C13-36)*(E13-18))/1000000 -> 0.441048 | X13: =(C13*100)/1000000 -> 0.06 | Y13: =((E13-36)*D13)/1000000 -> 0.4584
C14: 600 | D14: 600 | E14: 1400 | G14: FALSE | H14: 0 | I14: FALSE | J14: 0 | K14: 0 | L14: TRUE | M14: 1 | N14: TRUE | O14: 0 | Q14: =T14+(IF(G14=TRUE,S14,0))+(IF(H14>0,U14,0))+(IF(L14=TRUE,W14,0))+(IF(M14>0,V14,0))+(IF(N14=TRUE,X14,0)) -> 3.314856 | R14: =IF(Q14>0,Q14,0) -> 3.314856 | S14: =C14*E14/1000000 -> 0.84 | T14: =((C14*D14)+(C14*E14*2)+(2*((C14-36)*100)))/1000000 -> 2.1528 | U14: =(((((C14-36)-75)*K14)/1000000)*H14)+(((((C14-36)-87)*J14)/1000000)*H14) -> 0 | V14: =((C14-36)*(D14-28))/1000000 -> 0.322608 | W14: =((C14-36)*(E14-18))/1000000 -> 0.779448 | X14: =(C14*100)/1000000 -> 0.06 | Y14: =((E14-36)*D14)/1000000 -> 0.8184
C15: 600 | D15: 600 | E15: 714 | G15: FALSE | H15: 0 | I15: FALSE | J15: 0 | K15: 0 | L15: TRUE | M15: 1 | N15: TRUE | O15: 0 | Q15: =T15+(IF(G15=TRUE,S15,0))+(IF(H15>0,U15,0))+(IF(L15=TRUE,W15,0))+(IF(M15>0,V15,0))+(IF(N15=TRUE,X15,0)) -> 2.104752 | R15: =IF(Q15>0,Q15,0) -> 2.104752 | S15: =C15*E15/1000000 -> 0.4284 | T15: =((C15*D15)+(C15*E15*2)+(2*((C15-36)*100)))/1000000 -> 1.3296 | U15: =(((((C15-36)-75)*K15)/1000000)*H15)+(((((C15-36)-87)*J15)/1000000)*H15) -> 0 | V15: =((C15-36)*(D15-28))/1000000 -> 0.322608 | W15: =((C15-36)*(E15-18))/1000000 -> 0.392544 | X15: =(C15*100)/1000000 -> 0.06 | Y15: =((E15-36)*D15)/1000000 -> 0.4068
C16: 600 | D16: 600 | E16: 714 | G16: FALSE | H16: 0 | I16: FALSE | J16: 0 | K16: 0 | L16: TRUE | M16: 1 | N16: TRUE | O16: 0 | Q16: =T16+(IF(G16=TRUE,S16,0))+(IF(H16>0,U16,0))+(IF(L16=TRUE,W16,0))+(IF(M16>0,V16,0))+(IF(N16=TRUE,X16,0)) -> 2.104752 | R16: =IF(Q16>0,Q16,0) -> 2.104752 | S16: =C16*E16/1000000 -> 0.4284 | T16: =((C16*D16)+(C16*E16*2)+(2*((C16-36)*100)))/1000000 -> 1.3296 | U16: =(((((C16-36)-75)*K16)/1000000)*H16)+(((((C16-36)-87)*J16)/1000000)*H16) -> 0 | V16: =((C16-36)*(D16-28))/1000000 -> 0.322608 | W16: =((C16-36)*(E16-18))/1000000 -> 0.392544 | X16: =(C16*100)/1000000 -> 0.06 | Y16: =((E16-36)*D16)/1000000 -> 0.4068
C17: 600 | D17: 600 | E17: 714 | G17: FALSE | H17: 0 | I17: FALSE | J17: 0 | K17: 0 | L17: TRUE | M17: 1 | N17: TRUE | O17: 0 | Q17: =T17+(IF(G17=TRUE,S17,0))+(IF(H17>0,U17,0))+(IF(L17=TRUE,W17,0))+(IF(M17>0,V17,0))+(IF(N17=TRUE,X17,0)) -> 2.104752 | R17: =IF(Q17>0,Q17,0) -> 2.104752 | S17: =C17*E17/1000000 -> 0.4284 | T17: =((C17*D17)+(C17*E17*2)+(2*((C17-36)*100)))/1000000 -> 1.3296 | U17: =(((((C17-36)-75)*K17)/1000000)*H17)+(((((C17-36)-87)*J17)/1000000)*H17) -> 0 | V17: =((C17-36)*(D17-28))/1000000 -> 0.322608 | W17: =((C17-36)*(E17-18))/1000000 -> 0.392544 | X17: =(C17*100)/1000000 -> 0.06 | Y17: =((E17-36)*D17)/1000000 -> 0.4068
C18: 446 | D18: 600 | E18: 714 | G18: FALSE | H18: 0 | I18: FALSE | J18: 0 | K18: 0 | L18: TRUE | M18: 1 | N18: TRUE | O18: 0 | Q18: =T18+(IF(G18=TRUE,S18,0))+(IF(H18>0,U18,0))+(IF(L18=TRUE,W18,0))+(IF(M18>0,V18,0))+(IF(N18=TRUE,X18,0)) -> 1.550968 | R18: =IF(Q18>0,Q18,0) -> 1.550968 | S18: =C18*E18/1000000 -> 0.318444 | T18: =((C18*D18)+(C18*E18*2)+(2*((C18-36)*100)))/1000000 -> 0.986488 | U18: =(((((C18-36)-75)*K18)/1000000)*H18)+(((((C18-36)-87)*J18)/1000000)*H18) -> 0 | V18: =((C18-36)*(D18-28))/1000000 -> 0.23452 | W18: =((C18-36)*(E18-18))/1000000 -> 0.28536 | X18: =(C18*100)/1000000 -> 0.0446 | Y18: =((E18-36)*D18)/1000000 -> 0.4068
C19: 446 | D19: 600 | E19: 900 | G19: FALSE | H19: 0 | I19: FALSE | J19: 0 | K19: 0 | L19: TRUE | M19: 2 | N19: TRUE | O19: 0 | Q19: =T19+(IF(G19=TRUE,S19,0))+(IF(H19>0,U19,0))+(IF(L19=TRUE,W19,0))+(IF(M19>0,V19,0))+(IF(N19=TRUE,X19,0)) -> 1.79314 | R19: =IF(Q19>0,Q19,0) -> 1.79314 | S19: =C19*E19/1000000 -> 0.4014 | T19: =((C19*D19)+(C19*E19*2)+(2*((C19-36)*100)))/1000000 -> 1.1524 | U19: =(((((C19-36)-75)*K19)/1000000)*H19)+(((((C19-36)-87)*J19)/1000000)*H19) -> 0 | V19: =((C19-36)*(D19-28))/1000000 -> 0.23452 | W19: =((C19-36)*(E19-18))/1000000 -> 0.36162 | X19: =(C19*100)/1000000 -> 0.0446 | Y19: =((E19-36)*D19)/1000000 -> 0.5184
C20: 600 | D20: 600 | E20: 900 | G20: FALSE | H20: 0 | I20: FALSE | J20: 0 | K20: 0 | L20: TRUE | M20: 2 | N20: TRUE | O20: 0 | Q20: =T20+(IF(G20=TRUE,S20,0))+(IF(H20>0,U20,0))+(IF(L20=TRUE,W20,0))+(IF(M20>0,V20,0))+(IF(N20=TRUE,X20,0)) -> 2.432856 | R20: =IF(Q20>0,Q20,0) -> 2.432856 | S20: =C20*E20/1000000 -> 0.54 | T20: =((C20*D20)+(C20*E20*2)+(2*((C20-36)*100)))/1000000 -> 1.5528 | U20: =(((((C20-36)-75)*K20)/1000000)*H20)+(((((C20-36)-87)*J20)/1000000)*H20) -> 0 | V20: =((C20-36)*(D20-28))/1000000 -> 0.322608 | W20: =((C20-36)*(E20-18))/1000000 -> 0.497448 | X20: =(C20*100)/1000000 -> 0.06 | Y20: =((E20-36)*D20)/1000000 -> 0.5184
... C31: 1000 | D31: 600 | E31: 900 | G31: FALSE | H31: 0 | I31: FALSE | J31: 0 | K31: 0 | L31: TRUE | M31: 1 | N31: TRUE | O31: 1 | Q31: =T31+(IF(G31=TRUE,S31,0))+(IF(H31>0,U31,0))+(IF(L31=TRUE,W31,0))+(IF(M31>0,V31,0))+(IF(N31=TRUE,X31,0)) -> 4.094456 | R31: =IF(Q31>0,Q31,0) -> 4.094456 | S31: =C31*E31/1000000 -> 0.9 | T31: =((C31*D31)+(C31*E31*2)+(2*((C31-36)*100)))/1000000 -> 2.5928 | U31: =(((((C31-36)-75)*K31)/1000000)*H31)+(((((C31-36)-87)*J31)/1000000)*H31) -> 0 | V31: =((C31-36)*(D31-28))/1000000 -> 0.551408 | W31: =((C31-36)*(E31-18))/1000000 -> 0.850248 | X31: =(C31*100)/1000000 -> 0.1 | Y31: =((E31-36)*D31)/1000000 -> 0.5184
G32: FALSE | H32: 0 | I32: FALSE | J32: 0 | K32: 0 | L32: FALSE | M32: 0 | N32: FALSE | O32: 0 | Q32: =T32+(IF(G32=TRUE,S32,0))+(IF(H32>0,U32,0))+(IF(L32=TRUE,W32,0))+(IF(M32>0,V32,0))+(IF(N32=TRUE,X32,0)) -> -0.0072 | R32: =IF(Q32>0,Q32,0) -> 0 | S32: =C32*E32/1000000 -> 0 | T32: =((C32*D32)+(C32*E32*2)+(2*((C32-36)*100)))/1000000 -> -0.0072 | U32: =(((((C32-36)-75)*K32)/1000000)*H32)+(((((C32-36)-87)*J32)/1000000)*H32) -> 0 | V32: =((C32-36)*(D32-28))/1000000 -> 0.001008 | W32: =((C32-36)*(E32-18))/1000000 -> 0.000648 | X32: =(C32*100)/1000000 -> 0 | Y32: =((E32-36)*D32)/1000000 -> 0
G33: FALSE | H33: 0 | I33: FALSE | J33: 0 | K33: 0 | L33: FALSE | M33: 0 | N33: FALSE | O33: 0 | Q33: =T33+(IF(G33=TRUE,S33,0))+(IF(H33>0,U33,0))+(IF(L33=TRUE,W33,0))+(IF(M33>0,V33,0))+(IF(N33=TRUE,X33,0)) -> -0.0072 | R33: =IF(Q33>0,Q33,0) -> 0 | S33: =C33*E33/1000000 -> 0 | T33: =((C33*D33)+(C33*E33*2)+(2*((C33-36)*100)))/1000000 -> -0.0072 | U33: =(((((C33-36)-75)*K33)/1000000)*H33)+(((((C33-36)-87)*J33)/1000000)*H33) -> 0 | V33: =((C33-36)*(D33-28))/1000000 -> 0.001008 | W33: =((C33-36)*(E33-18))/1000000 -> 0.000648 | X33: =(C33*100)/1000000 -> 0 | Y33: =((E33-36)*D33)/1000000 -> 0
G34: FALSE | H34: 0 | I34: FALSE | J34: 0 | K34: 0 | L34: FALSE | M34: 0 | N34: FALSE | O34: 0 | Q34: =T34+(IF(G34=TRUE,S34,0))+(IF(H34>0,U34,0))+(IF(L34=TRUE,W34,0))+(IF(M34>0,V34,0))+(IF(N34=TRUE,X34,0)) -> -0.0072 | R34: =IF(Q34>0,Q34,0) -> 0 | S34: =C34*E34/1000000 -> 0 | T34: =((C34*D34)+(C34*E34*2)+(2*((C34-36)*100)))/1000000 -> -0.0072 | U34: =(((((C34-36)-75)*K34)/1000000)*H34)+(((((C34-36)-87)*J34)/1000000)*H34) -> 0 | V34: =((C34-36)*(D34-28))/1000000 -> 0.001008 | W34: =((C34-36)*(E34-18))/1000000 -> 0.000648 | X34: =(C34*100)/1000000 -> 0 | Y34: =((E34-36)*D34)/1000000 -> 0
G35: FALSE | H35: 0 | I35: FALSE | J35: 0 | K35: 0 | L35: FALSE | M35: 0 | N35: FALSE | O35: 0 | Q35: =T35+(IF(G35=TRUE,S35,0))+(IF(H35>0,U35,0))+(IF(L35=TRUE,W35,0))+(IF(M35>0,V35,0))+(IF(N35=TRUE,X35,0)) -> -0.0072 | R35: =IF(Q35>0,Q35,0) -> 0 | S35: =C35*E35/1000000 -> 0 | T35: =((C35*D35)+(C35*E35*2)+(2*((C35-36)*100)))/1000000 -> -0.0072 | U35: =(((((C35-36)-75)*K35)/1000000)*H35)+(((((C35-36)-87)*J35)/1000000)*H35) -> 0 | V35: =((C35-36)*(D35-28))/1000000 -> 0.001008 | W35: =((C35-36)*(E35-18))/1000000 -> 0.000648 | X35: =(C35*100)/1000000 -> 0 | Y35: =((E35-36)*D35)/1000000 -> 0
G36: FALSE | H36: 0 | I36: FALSE | J36: 0 | K36: 0 | L36: FALSE | M36: 0 | N36: FALSE | O36: 0 | Q36: =T36+(IF(G36=TRUE,S36,0))+(IF(H36>0,U36,0))+(IF(L36=TRUE,W36,0))+(IF(M36>0,V36,0))+(IF(N36=TRUE,X36,0)) -> -0.0072 | R36: =IF(Q36>0,Q36,0) -> 0 | S36: =C36*E36/1000000 -> 0 | T36: =((C36*D36)+(C36*E36*2)+(2*((C36-36)*100)))/1000000 -> -0.0072 | U36: =(((((C36-36)-75)*K36)/1000000)*H36)+(((((C36-36)-87)*J36)/1000000)*H36) -> 0 | V36: =((C36-36)*(D36-28))/1000000 -> 0.001008 | W36: =((C36-36)*(E36-18))/1000000 -> 0.000648 | X36: =(C36*100)/1000000 -> 0 | Y36: =((E36-36)*D36)/1000000 -> 0
G37: FALSE | H37: 0 | I37: FALSE | J37: 0 | K37: 0 | L37: FALSE | M37: 0 | N37: FALSE | O37: 0 | Q37: =T37+(IF(G37=TRUE,S37,0))+(IF(H37>0,U37,0))+(IF(L37=TRUE,W37,0))+(IF(M37>0,V37,0))+(IF(N37=TRUE,X37,0)) -> -0.0072 | R37: =IF(Q37>0,Q37,0) -> 0 | S37: =C37*E37/1000000 -> 0 | T37: =((C37*D37)+(C37*E37*2)+(2*((C37-36)*100)))/1000000 -> -0.0072 | U37: =(((((C37-36)-75)*K37)/1000000)*H37)+(((((C37-36)-87)*J37)/1000000)*H37) -> 0 | V37: =((C37-36)*(D37-28))/1000000 -> 0.001008 | W37: =((C37-36)*(E37-18))/1000000 -> 0.000648 | X37: =(C37*100)/1000000 -> 0 | Y37: =((E37-36)*D37)/1000000 -> 0
G38: FALSE | H38: 0 | I38: FALSE | J38: 0 | K38: 0 | L38: FALSE | M38: 0 | N38: FALSE | O38: 0 | Q38: =T38+(IF(G38=TRUE,S38,0))+(IF(H38>0,U38,0))+(IF(L38=TRUE,W38,0))+(IF(M38>0,V38,0))+(IF(N38=TRUE,X38,0)) -> -0.0072 | R38: =IF(Q38>0,Q38,0) -> 0 | S38: =C38*E38/1000000 -> 0 | T38: =((C38*D38)+(C38*E38*2)+(2*((C38-36)*100)))/1000000 -> -0.0072 | U38: =(((((C38-36)-75)*K38)/1000000)*H38)+(((((C38-36)-87)*J38)/1000000)*H38) -> 0 | V38: =((C38-36)*(D38-28))/1000000 -> 0.001008 | W38: =((C38-36)*(E38-18))/1000000 -> 0.000648 | X38: =(C38*100)/1000000 -> 0 | Y38: =((E38-36)*D38)/1000000 -> 0
L42: Viso plokštės: | M42: =SUM(R8:R38) -> 68.751676

Sheet PASIULYMAS
B5: KOMERCINIS PASIŪLYMAS
C7: Numeris | D7: CP/EPALGB1
C8: Data | D8: =TODAY() -> 46315
C9: Galiojimo data | D9: =TODAY()+14 -> 46329
B11: Tiekėjas | G11: Užsakovas
B12: IĮ "Buki kaltai" | G12: Egle Preise
B13: 305189636
B14: LT100012484610
B15: Šilo g. 6, Lekėčiai, Šakių r.
B16: ="062533752" -> 062533752
A18: Nr. | B18: Produktas/paslauga | E18: Kaina | F18: Kiekis | G18: Kaina už visus | H18: PVM | I18: Kaina su mokesčiais
A19: 1 | B19: Koridoriaus spinta | E19: =Samata1!F27 -> 2882.091 | F19: 1 | G19: =IF(ISBLANK(E19),"",E19*F19) -> 2882.091 | H19: =IF(ISBLANK(E19),"",G19*21%) -> 605.23911 | I19: =IF(ISBLANK(E19),"",G19+H19) -> 3487.3301
A20: 2 | B20: Televizoriaus baldas | E20: =Samata1!F45+2000 -> 3419.9885 | F20: 1 | G20: =IF(ISBLANK(E20),"",E20*F20) -> 3419.9885 | H20: =IF(ISBLANK(E20),"",G20*21%) -> 718.19759 | I20: =IF(ISBLANK(E20),"",G20+H20) -> 4138.1861
A21: 3 | B21: Virtuvės sala | E21: =Samata1!F59 -> 4102.1142 | F21: 1 | G21: =IF(ISBLANK(E21),"",E21*F21) -> 4102.1142 | H21: =IF(ISBLANK(E21),"",G21*21%) -> 861.44399 | I21: =IF(ISBLANK(E21),"",G21+H21) -> 4963.5582
A22: 4 | B22: Virtuvės baldas | E22: =Samata1!F77 -> 10095.641 | F22: 1 | G22: =IF(ISBLANK(E22),"",E22*F22) -> 10095.641 | H22: =IF(ISBLANK(E22),"",G22*21%) -> 2120.0846 | I22: =IF(ISBLANK(E22),"",G22+H22) -> 12215.726
A23: 5 | B23: San. mazgo baldas 1 | E23: =Samata1!F105 -> 813.09648 | F23: 1 | G23: =IF(ISBLANK(E23),"",E23*F23) -> 813.09648 | H23: =IF(ISBLANK(E23),"",G23*21%) -> 170.75026 | I23: =IF(ISBLANK(E23),"",G23+H23) -> 983.84674
A24: 6 | B24: San. mazgo baldas 2 | E24: =Samata1!F117 -> 299.17524 | F24: 1 | G24: =IF(ISBLANK(E24),"",E24*F24) -> 299.17524 | H24: =IF(ISBLANK(E24),"",G24*21%) -> 62.8268 | I24: =IF(ISBLANK(E24),"",G24+H24) -> 362.00204
A25: 7 | B25: San. mazgo baldas 3 | E25: =Samata1!F129 -> 942.03704 | F25: 1 | G25: =IF(ISBLANK(E25),"",E25*F25) -> 942.03704 | H25: =IF(ISBLANK(E25),"",G25*21%) -> 197.82778 | I25: =IF(ISBLANK(E25),"",G25+H25) -> 1139.8648
A26: 8 | B26: Miegamojo spinta | E26: =Samata1!F142 -> 6068.0427 | F26: 1 | G26: =IF(ISBLANK(E26),"",E26*F26) -> 6068.0427 | H26: =IF(ISBLANK(E26),"",G26*21%) -> 1274.289 | I26: =IF(ISBLANK(E26),"",G26+H26) -> 7342.3317
A27: 9 | B27: Darbo stalas | E27: =Samata1!F175 -> 1722.21 | F27: 1 | G27: =IF(ISBLANK(E27),"",E27*F27) -> 1722.21 | H27: =IF(ISBLANK(E27),"",G27*21%) -> 361.6641 | I27: =IF(ISBLANK(E27),"",G27+H27) -> 2083.8741
A28: 10 | B28: Darbo kambario spinta | E28: =Samata1!F189 -> 3248.6762 | F28: 1 | G28: =IF(ISBLANK(E28),"",E28*F28) -> 3248.6762 | H28: =IF(ISBLANK(E28),"",G28*21%) -> 682.222 | I28: =IF(ISBLANK(E28),"",G28+H28) -> 3930.8982
A29: 11 | B29: Skalbyklos baldas | E29: =Samata1!F206 -> 1246.5835 | F29: 1 | G29: =IF(ISBLANK(E29),"",E29*F29) -> 1246.5835 | H29: =IF(ISBLANK(E29),"",G29*21%) -> 261.78254 | I29: =IF(ISBLANK(E29),"",G29+H29) -> 1508.3661
A30: 12 | B30: Matavimas | E30: 600 | F30: 1 | G30: =IF(ISBLANK(E30),"",E30*F30) -> 600 | H30: =IF(ISBLANK(E30),"",G30*21%) -> 126 | I30: =IF(ISBLANK(E30),"",G30+H30) -> 726
A31: 13 | B31: Pristatymas | E31: 800 | F31: 1 | G31: =IF(ISBLANK(E31),"",E31*F31) -> 800 | H31: =IF(ISBLANK(E31),"",G31*21%) -> 168 | I31: =IF(ISBLANK(E31),"",G31+H31) -> 968
A32: 14 | B32: Montavimas | E32: 40 | F32: =2*10*11 -> 220 | G32: =IF(ISBLANK(E32),"",E32*F32) -> 8800 | H32: =IF(ISBLANK(E32),"",G32*21%) -> 1848 | I32: =IF(ISBLANK(E32),"",G32+H32) -> 10648
H34: Kaina | I34: =SUM(G19:G32) -> 45039.656
H35: PVM | I35: =SUM(H19:H32) -> 9458.3278
H36: Nuolaida
H37: Viso | I37: =IF(I36="",I34+I35,(I34+I35)-I36) -> 54497.984
A40: ● Kainos gali keistis atsisakius vienos ar kitos pozicijos iš pasiūlymo ● Kainos gali keistis keičiant užklausoje pateiktus ir/ar telefonu aptartus duomenis iki pasiūlymo galiojimo pabaigos ● Pristatymo kaštai ir montavimo paslauga neįskaičiuota, nebent pasiūlyme nurodyta kitaip
